[2025-03-30T16:45:46.935+0000] {local_task_job_runner.py:120} INFO - ::group::Pre task execution logs
[2025-03-30T16:45:46.944+0000] {taskinstance.py:2076} INFO - Dependencies all met for dep_context=non-requeueable deps ti=<TaskInstance: sensor_data_pipelinew.create_kafka_sink manual__2025-03-30T16:45:43.154862+00:00 [queued]>
[2025-03-30T16:45:46.947+0000] {taskinstance.py:2076} INFO - Dependencies all met for dep_context=requeueable deps ti=<TaskInstance: sensor_data_pipelinew.create_kafka_sink manual__2025-03-30T16:45:43.154862+00:00 [queued]>
[2025-03-30T16:45:46.947+0000] {taskinstance.py:2306} INFO - Starting attempt 1 of 2
[2025-03-30T16:45:46.953+0000] {taskinstance.py:2330} INFO - Executing <Task(PythonOperator): create_kafka_sink> on 2025-03-30 16:45:43.154862+00:00
[2025-03-30T16:45:46.955+0000] {standard_task_runner.py:64} INFO - Started process 176 to run task
[2025-03-30T16:45:46.957+0000] {standard_task_runner.py:90} INFO - Running: ['airflow', 'tasks', 'run', 'sensor_data_pipelinew', 'create_kafka_sink', 'manual__2025-03-30T16:45:43.154862+00:00', '--job-id', '15', '--raw', '--subdir', 'DAGS_FOLDER/pipeline.py', '--cfg-path', '/tmp/tmp5dkqmh2b']
[2025-03-30T16:45:46.958+0000] {standard_task_runner.py:91} INFO - Job 15: Subtask create_kafka_sink
[2025-03-30T16:45:46.974+0000] {task_command.py:426} INFO - Running <TaskInstance: sensor_data_pipelinew.create_kafka_sink manual__2025-03-30T16:45:43.154862+00:00 [running]> on host airflow
[2025-03-30T16:45:47.000+0000] {taskinstance.py:2648} INFO - Exporting env vars: AIRFLOW_CTX_DAG_OWNER='airflow' AIRFLOW_CTX_DAG_ID='sensor_data_pipelinew' AIRFLOW_CTX_TASK_ID='create_kafka_sink' AIRFLOW_CTX_EXECUTION_DATE='2025-03-30T16:45:43.154862+00:00' AIRFLOW_CTX_TRY_NUMBER='1' AIRFLOW_CTX_DAG_RUN_ID='manual__2025-03-30T16:45:43.154862+00:00'
[2025-03-30T16:45:47.000+0000] {taskinstance.py:430} INFO - ::endgroup::
[2025-03-30T16:45:47.026+0000] {taskinstance.py:441} INFO - ::group::Post task execution logs
[2025-03-30T16:45:47.028+0000] {taskinstance.py:2905} ERROR - Task failed with exception
Traceback (most recent call last):
  File "/opt/airflow/dags/pipeline.py", line 65, in create_kafka_sink
    response.raise_for_status()
  File "/home/airflow/.local/lib/python3.9/site-packages/requests/models.py", line 1021, in raise_for_status
    raise HTTPError(http_error_msg, response=self)
requests.exceptions.HTTPError: 409 Client Error: Conflict for url: http://kafka-connect:8083/connectors

During handling of the above exception, another exception occurred:

Traceback (most recent call last):
  File "/home/airflow/.local/lib/python3.9/site-packages/airflow/models/taskinstance.py", line 465, in _execute_task
    result = _execute_callable(context=context, **execute_callable_kwargs)
  File "/home/airflow/.local/lib/python3.9/site-packages/airflow/models/taskinstance.py", line 432, in _execute_callable
    return execute_callable(context=context, **execute_callable_kwargs)
  File "/home/airflow/.local/lib/python3.9/site-packages/airflow/models/baseoperator.py", line 401, in wrapper
    return func(self, *args, **kwargs)
  File "/home/airflow/.local/lib/python3.9/site-packages/airflow/operators/python.py", line 235, in execute
    return_value = self.execute_callable()
  File "/home/airflow/.local/lib/python3.9/site-packages/airflow/operators/python.py", line 252, in execute_callable
    return self.python_callable(*self.op_args, **self.op_kwargs)
  File "/opt/airflow/dags/pipeline.py", line 68, in create_kafka_sink
    raise AirflowException(f"Failed to create Kafka sink connector: {e}")
airflow.exceptions.AirflowException: Failed to create Kafka sink connector: 409 Client Error: Conflict for url: http://kafka-connect:8083/connectors
[2025-03-30T16:45:47.030+0000] {taskinstance.py:1206} INFO - Marking task as UP_FOR_RETRY. dag_id=sensor_data_pipelinew, task_id=create_kafka_sink, run_id=manual__2025-03-30T16:45:43.154862+00:00, execution_date=20250330T164543, start_date=20250330T164546, end_date=20250330T164547
[2025-03-30T16:45:47.037+0000] {standard_task_runner.py:110} ERROR - Failed to execute job 15 for task create_kafka_sink (Failed to create Kafka sink connector: 409 Client Error: Conflict for url: http://kafka-connect:8083/connectors; 176)
[2025-03-30T16:45:47.055+0000] {local_task_job_runner.py:243} INFO - Task exited with return code 1
[2025-03-30T16:45:47.068+0000] {taskinstance.py:3503} INFO - 0 downstream tasks scheduled from follow-on schedule check
[2025-03-30T16:45:47.068+0000] {local_task_job_runner.py:222} INFO - ::endgroup::
