[2025-03-30T16:32:59.920+0000] {local_task_job_runner.py:120} INFO - ::group::Pre task execution logs
[2025-03-30T16:32:59.931+0000] {taskinstance.py:2076} INFO - Dependencies all met for dep_context=non-requeueable deps ti=<TaskInstance: sensor_data_pipeline.create_kafka_sink manual__2025-03-30T16:32:55.536979+00:00 [queued]>
[2025-03-30T16:32:59.933+0000] {taskinstance.py:2076} INFO - Dependencies all met for dep_context=requeueable deps ti=<TaskInstance: sensor_data_pipeline.create_kafka_sink manual__2025-03-30T16:32:55.536979+00:00 [queued]>
[2025-03-30T16:32:59.933+0000] {taskinstance.py:2306} INFO - Starting attempt 1 of 2
[2025-03-30T16:32:59.939+0000] {taskinstance.py:2330} INFO - Executing <Task(PythonOperator): create_kafka_sink> on 2025-03-30 16:32:55.536979+00:00
[2025-03-30T16:32:59.941+0000] {standard_task_runner.py:64} INFO - Started process 211 to run task
[2025-03-30T16:32:59.943+0000] {standard_task_runner.py:90} INFO - Running: ['airflow', 'tasks', 'run', 'sensor_data_pipeline', 'create_kafka_sink', 'manual__2025-03-30T16:32:55.536979+00:00', '--job-id', '3', '--raw', '--subdir', 'DAGS_FOLDER/pipeline.py', '--cfg-path', '/tmp/tmpagycizhx']
[2025-03-30T16:32:59.944+0000] {standard_task_runner.py:91} INFO - Job 3: Subtask create_kafka_sink
[2025-03-30T16:32:59.960+0000] {task_command.py:426} INFO - Running <TaskInstance: sensor_data_pipeline.create_kafka_sink manual__2025-03-30T16:32:55.536979+00:00 [running]> on host airflow
[2025-03-30T16:32:59.988+0000] {taskinstance.py:2648} INFO - Exporting env vars: AIRFLOW_CTX_DAG_OWNER='airflow' AIRFLOW_CTX_DAG_ID='sensor_data_pipeline' AIRFLOW_CTX_TASK_ID='create_kafka_sink' AIRFLOW_CTX_EXECUTION_DATE='2025-03-30T16:32:55.536979+00:00' AIRFLOW_CTX_TRY_NUMBER='1' AIRFLOW_CTX_DAG_RUN_ID='manual__2025-03-30T16:32:55.536979+00:00'
[2025-03-30T16:32:59.989+0000] {taskinstance.py:430} INFO - ::endgroup::
[2025-03-30T16:32:59.995+0000] {taskinstance.py:441} INFO - ::group::Post task execution logs
[2025-03-30T16:32:59.996+0000] {taskinstance.py:2905} ERROR - Task failed with exception
Traceback (most recent call last):
  File "/home/airflow/.local/lib/python3.9/site-packages/urllib3/connection.py", line 174, in _new_conn
    conn = connection.create_connection(
  File "/home/airflow/.local/lib/python3.9/site-packages/urllib3/util/connection.py", line 95, in create_connection
    raise err
  File "/home/airflow/.local/lib/python3.9/site-packages/urllib3/util/connection.py", line 85, in create_connection
    sock.connect(sa)
ConnectionRefusedError: [Errno 111] Connection refused

During handling of the above exception, another exception occurred:

Traceback (most recent call last):
  File "/home/airflow/.local/lib/python3.9/site-packages/urllib3/connectionpool.py", line 715, in urlopen
    httplib_response = self._make_request(
  File "/home/airflow/.local/lib/python3.9/site-packages/urllib3/connectionpool.py", line 416, in _make_request
    conn.request(method, url, **httplib_request_kw)
  File "/home/airflow/.local/lib/python3.9/site-packages/urllib3/connection.py", line 244, in request
    super(HTTPConnection, self).request(method, url, body=body, headers=headers)
  File "/usr/local/lib/python3.9/http/client.py", line 1285, in request
    self._send_request(method, url, body, headers, encode_chunked)
  File "/usr/local/lib/python3.9/http/client.py", line 1331, in _send_request
    self.endheaders(body, encode_chunked=encode_chunked)
  File "/usr/local/lib/python3.9/http/client.py", line 1280, in endheaders
    self._send_output(message_body, encode_chunked=encode_chunked)
  File "/usr/local/lib/python3.9/http/client.py", line 1040, in _send_output
    self.send(msg)
  File "/usr/local/lib/python3.9/http/client.py", line 980, in send
    self.connect()
  File "/home/airflow/.local/lib/python3.9/site-packages/urllib3/connection.py", line 205, in connect
    conn = self._new_conn()
  File "/home/airflow/.local/lib/python3.9/site-packages/urllib3/connection.py", line 186, in _new_conn
    raise NewConnectionError(
urllib3.exceptions.NewConnectionError: <urllib3.connection.HTTPConnection object at 0xffff8734e4f0>: Failed to establish a new connection: [Errno 111] Connection refused

During handling of the above exception, another exception occurred:

Traceback (most recent call last):
  File "/home/airflow/.local/lib/python3.9/site-packages/requests/adapters.py", line 486, in send
    resp = conn.urlopen(
  File "/home/airflow/.local/lib/python3.9/site-packages/urllib3/connectionpool.py", line 801, in urlopen
    retries = retries.increment(
  File "/home/airflow/.local/lib/python3.9/site-packages/urllib3/util/retry.py", line 594, in increment
    raise MaxRetryError(_pool, url, error or ResponseError(cause))
urllib3.exceptions.MaxRetryError: HTTPConnectionPool(host='localhost', port=8083): Max retries exceeded with url: /connectors (Caused by NewConnectionError('<urllib3.connection.HTTPConnection object at 0xffff8734e4f0>: Failed to establish a new connection: [Errno 111] Connection refused'))

During handling of the above exception, another exception occurred:

Traceback (most recent call last):
  File "/home/airflow/.local/lib/python3.9/site-packages/airflow/models/taskinstance.py", line 465, in _execute_task
    result = _execute_callable(context=context, **execute_callable_kwargs)
  File "/home/airflow/.local/lib/python3.9/site-packages/airflow/models/taskinstance.py", line 432, in _execute_callable
    return execute_callable(context=context, **execute_callable_kwargs)
  File "/home/airflow/.local/lib/python3.9/site-packages/airflow/models/baseoperator.py", line 401, in wrapper
    return func(self, *args, **kwargs)
  File "/home/airflow/.local/lib/python3.9/site-packages/airflow/operators/python.py", line 235, in execute
    return_value = self.execute_callable()
  File "/home/airflow/.local/lib/python3.9/site-packages/airflow/operators/python.py", line 252, in execute_callable
    return self.python_callable(*self.op_args, **self.op_kwargs)
  File "/opt/airflow/dags/pipeline.py", line 58, in create_kafka_sink
    response = requests.post(
  File "/home/airflow/.local/lib/python3.9/site-packages/requests/api.py", line 115, in post
    return request("post", url, data=data, json=json, **kwargs)
  File "/home/airflow/.local/lib/python3.9/site-packages/requests/api.py", line 59, in request
    return session.request(method=method, url=url, **kwargs)
  File "/home/airflow/.local/lib/python3.9/site-packages/requests/sessions.py", line 589, in request
    resp = self.send(prep, **send_kwargs)
  File "/home/airflow/.local/lib/python3.9/site-packages/requests/sessions.py", line 703, in send
    r = adapter.send(request, **kwargs)
  File "/home/airflow/.local/lib/python3.9/site-packages/requests/adapters.py", line 519, in send
    raise ConnectionError(e, request=request)
requests.exceptions.ConnectionError: HTTPConnectionPool(host='localhost', port=8083): Max retries exceeded with url: /connectors (Caused by NewConnectionError('<urllib3.connection.HTTPConnection object at 0xffff8734e4f0>: Failed to establish a new connection: [Errno 111] Connection refused'))
[2025-03-30T16:33:00.000+0000] {taskinstance.py:1206} INFO - Marking task as UP_FOR_RETRY. dag_id=sensor_data_pipeline, task_id=create_kafka_sink, run_id=manual__2025-03-30T16:32:55.536979+00:00, execution_date=20250330T163255, start_date=20250330T163259, end_date=20250330T163300
[2025-03-30T16:33:00.005+0000] {standard_task_runner.py:110} ERROR - Failed to execute job 3 for task create_kafka_sink (HTTPConnectionPool(host='localhost', port=8083): Max retries exceeded with url: /connectors (Caused by NewConnectionError('<urllib3.connection.HTTPConnection object at 0xffff8734e4f0>: Failed to establish a new connection: [Errno 111] Connection refused')); 211)
[2025-03-30T16:33:00.040+0000] {local_task_job_runner.py:243} INFO - Task exited with return code 1
[2025-03-30T16:33:00.052+0000] {taskinstance.py:3503} INFO - 0 downstream tasks scheduled from follow-on schedule check
[2025-03-30T16:33:00.052+0000] {local_task_job_runner.py:222} INFO - ::endgroup::
