[2025-04-06T19:01:21.238+0000] {local_task_job_runner.py:120} INFO - ::group::Pre task execution logs
[2025-04-06T19:01:21.247+0000] {taskinstance.py:2076} INFO - Dependencies all met for dep_context=non-requeueable deps ti=<TaskInstance: sensor_data_pipeline.create_database manual__2025-04-06T19:01:12.100612+00:00 [queued]>
[2025-04-06T19:01:21.251+0000] {taskinstance.py:2076} INFO - Dependencies all met for dep_context=requeueable deps ti=<TaskInstance: sensor_data_pipeline.create_database manual__2025-04-06T19:01:12.100612+00:00 [queued]>
[2025-04-06T19:01:21.251+0000] {taskinstance.py:2306} INFO - Starting attempt 1 of 2
[2025-04-06T19:01:21.257+0000] {taskinstance.py:2330} INFO - Executing <Task(PythonOperator): create_database> on 2025-04-06 19:01:12.100612+00:00
[2025-04-06T19:01:21.259+0000] {standard_task_runner.py:64} INFO - Started process 194 to run task
[2025-04-06T19:01:21.261+0000] {standard_task_runner.py:90} INFO - Running: ['airflow', 'tasks', 'run', 'sensor_data_pipeline', 'create_database', 'manual__2025-04-06T19:01:12.100612+00:00', '--job-id', '92', '--raw', '--subdir', 'DAGS_FOLDER/pipeline.py', '--cfg-path', '/tmp/tmp59om2xm0']
[2025-04-06T19:01:21.262+0000] {standard_task_runner.py:91} INFO - Job 92: Subtask create_database
[2025-04-06T19:01:21.277+0000] {task_command.py:426} INFO - Running <TaskInstance: sensor_data_pipeline.create_database manual__2025-04-06T19:01:12.100612+00:00 [running]> on host airflow
[2025-04-06T19:01:21.305+0000] {taskinstance.py:2648} INFO - Exporting env vars: AIRFLOW_CTX_DAG_OWNER='airflow' AIRFLOW_CTX_DAG_ID='sensor_data_pipeline' AIRFLOW_CTX_TASK_ID='create_database' AIRFLOW_CTX_EXECUTION_DATE='2025-04-06T19:01:12.100612+00:00' AIRFLOW_CTX_TRY_NUMBER='1' AIRFLOW_CTX_DAG_RUN_ID='manual__2025-04-06T19:01:12.100612+00:00'
[2025-04-06T19:01:21.305+0000] {taskinstance.py:430} INFO - ::endgroup::
[2025-04-06T19:01:21.310+0000] {pipeline.py:106} INFO - Creating Hive database if it doesn't exist
[2025-04-06T19:01:21.313+0000] {base.py:84} INFO - Using connection ID 'hive_default' for task execution.
[2025-04-06T19:01:21.324+0000] {TSocket.py:149} INFO - Could not connect to ('192.168.97.6', 10000)
Traceback (most recent call last):
  File "/home/airflow/.local/lib/python3.9/site-packages/thrift/transport/TSocket.py", line 144, in open
    handle.connect(sockaddr)
ConnectionRefusedError: [Errno 111] Connection refused
[2025-04-06T19:01:21.325+0000] {TSocket.py:152} ERROR - Could not connect to any of [('192.168.97.6', 10000)]
[2025-04-06T19:01:21.325+0000] {pipeline.py:118} ERROR - Error creating database: Could not connect to any of [('192.168.97.6', 10000)]
Traceback (most recent call last):
  File "/opt/airflow/dags/pipeline.py", line 109, in create_database
    conn = hive_hook.get_conn()
  File "/home/airflow/.local/lib/python3.9/site-packages/airflow/providers/apache/hive/hooks/hive.py", line 886, in get_conn
    return connect(
  File "/home/airflow/.local/lib/python3.9/site-packages/pyhive/hive.py", line 143, in connect
    return Connection(*args, **kwargs)
  File "/home/airflow/.local/lib/python3.9/site-packages/pyhive/hive.py", line 269, in __init__
    self._transport.open()
  File "/home/airflow/.local/lib/python3.9/site-packages/thrift_sasl/__init__.py", line 74, in open
    self._trans.open()
  File "/home/airflow/.local/lib/python3.9/site-packages/thrift/transport/TSocket.py", line 153, in open
    raise TTransportException(type=TTransportException.NOT_OPEN, message=msg)
thrift.transport.TTransport.TTransportException: Could not connect to any of [('192.168.97.6', 10000)]
[2025-04-06T19:01:21.326+0000] {taskinstance.py:441} INFO - ::group::Post task execution logs
[2025-04-06T19:01:21.326+0000] {taskinstance.py:2905} ERROR - Task failed with exception
Traceback (most recent call last):
  File "/home/airflow/.local/lib/python3.9/site-packages/airflow/models/taskinstance.py", line 465, in _execute_task
    result = _execute_callable(context=context, **execute_callable_kwargs)
  File "/home/airflow/.local/lib/python3.9/site-packages/airflow/models/taskinstance.py", line 432, in _execute_callable
    return execute_callable(context=context, **execute_callable_kwargs)
  File "/home/airflow/.local/lib/python3.9/site-packages/airflow/models/baseoperator.py", line 401, in wrapper
    return func(self, *args, **kwargs)
  File "/home/airflow/.local/lib/python3.9/site-packages/airflow/operators/python.py", line 235, in execute
    return_value = self.execute_callable()
  File "/home/airflow/.local/lib/python3.9/site-packages/airflow/operators/python.py", line 252, in execute_callable
    return self.python_callable(*self.op_args, **self.op_kwargs)
  File "/opt/airflow/dags/pipeline.py", line 109, in create_database
    conn = hive_hook.get_conn()
  File "/home/airflow/.local/lib/python3.9/site-packages/airflow/providers/apache/hive/hooks/hive.py", line 886, in get_conn
    return connect(
  File "/home/airflow/.local/lib/python3.9/site-packages/pyhive/hive.py", line 143, in connect
    return Connection(*args, **kwargs)
  File "/home/airflow/.local/lib/python3.9/site-packages/pyhive/hive.py", line 269, in __init__
    self._transport.open()
  File "/home/airflow/.local/lib/python3.9/site-packages/thrift_sasl/__init__.py", line 74, in open
    self._trans.open()
  File "/home/airflow/.local/lib/python3.9/site-packages/thrift/transport/TSocket.py", line 153, in open
    raise TTransportException(type=TTransportException.NOT_OPEN, message=msg)
thrift.transport.TTransport.TTransportException: Could not connect to any of [('192.168.97.6', 10000)]
[2025-04-06T19:01:21.331+0000] {taskinstance.py:1206} INFO - Marking task as UP_FOR_RETRY. dag_id=sensor_data_pipeline, task_id=create_database, run_id=manual__2025-04-06T19:01:12.100612+00:00, execution_date=20250406T190112, start_date=20250406T190121, end_date=20250406T190121
[2025-04-06T19:01:21.337+0000] {standard_task_runner.py:110} ERROR - Failed to execute job 92 for task create_database (Could not connect to any of [('192.168.97.6', 10000)]; 194)
[2025-04-06T19:01:21.365+0000] {local_task_job_runner.py:243} INFO - Task exited with return code 1
[2025-04-06T19:01:21.376+0000] {taskinstance.py:3503} INFO - 0 downstream tasks scheduled from follow-on schedule check
[2025-04-06T19:01:21.376+0000] {local_task_job_runner.py:222} INFO - ::endgroup::
