[2025-04-06T18:59:15.959+0000] {local_task_job_runner.py:120} INFO - ::group::Pre task execution logs
[2025-04-06T18:59:15.969+0000] {taskinstance.py:2076} INFO - Dependencies all met for dep_context=non-requeueable deps ti=<TaskInstance: sensor_data_pipeline.create_database manual__2025-04-06T18:54:04.291387+00:00 [queued]>
[2025-04-06T18:59:15.973+0000] {taskinstance.py:2076} INFO - Dependencies all met for dep_context=requeueable deps ti=<TaskInstance: sensor_data_pipeline.create_database manual__2025-04-06T18:54:04.291387+00:00 [queued]>
[2025-04-06T18:59:15.974+0000] {taskinstance.py:2306} INFO - Starting attempt 2 of 2
[2025-04-06T18:59:15.980+0000] {taskinstance.py:2330} INFO - Executing <Task(PythonOperator): create_database> on 2025-04-06 18:54:04.291387+00:00
[2025-04-06T18:59:15.983+0000] {standard_task_runner.py:64} INFO - Started process 163 to run task
[2025-04-06T18:59:15.990+0000] {standard_task_runner.py:90} INFO - Running: ['airflow', 'tasks', 'run', 'sensor_data_pipeline', 'create_database', 'manual__2025-04-06T18:54:04.291387+00:00', '--job-id', '88', '--raw', '--subdir', 'DAGS_FOLDER/pipeline.py', '--cfg-path', '/tmp/tmpept3_i4o']
[2025-04-06T18:59:15.992+0000] {standard_task_runner.py:91} INFO - Job 88: Subtask create_database
[2025-04-06T18:59:16.021+0000] {task_command.py:426} INFO - Running <TaskInstance: sensor_data_pipeline.create_database manual__2025-04-06T18:54:04.291387+00:00 [running]> on host airflow
[2025-04-06T18:59:16.063+0000] {taskinstance.py:2648} INFO - Exporting env vars: AIRFLOW_CTX_DAG_OWNER='airflow' AIRFLOW_CTX_DAG_ID='sensor_data_pipeline' AIRFLOW_CTX_TASK_ID='create_database' AIRFLOW_CTX_EXECUTION_DATE='2025-04-06T18:54:04.291387+00:00' AIRFLOW_CTX_TRY_NUMBER='2' AIRFLOW_CTX_DAG_RUN_ID='manual__2025-04-06T18:54:04.291387+00:00'
[2025-04-06T18:59:16.064+0000] {taskinstance.py:430} INFO - ::endgroup::
[2025-04-06T18:59:16.075+0000] {pipeline.py:106} INFO - Creating Hive database if it doesn't exist
[2025-04-06T18:59:16.087+0000] {base.py:84} INFO - Using connection ID 'hive_default' for task execution.
[2025-04-06T18:59:16.104+0000] {TSocket.py:149} INFO - Could not connect to ('192.168.97.11', 10000)
Traceback (most recent call last):
  File "/home/airflow/.local/lib/python3.9/site-packages/thrift/transport/TSocket.py", line 144, in open
    handle.connect(sockaddr)
ConnectionRefusedError: [Errno 111] Connection refused
[2025-04-06T18:59:16.105+0000] {TSocket.py:152} ERROR - Could not connect to any of [('192.168.97.11', 10000)]
[2025-04-06T18:59:16.105+0000] {pipeline.py:118} ERROR - Error creating database: Could not connect to any of [('192.168.97.11', 10000)]
Traceback (most recent call last):
  File "/opt/airflow/dags/pipeline.py", line 109, in create_database
    conn = hive_hook.get_conn()
  File "/home/airflow/.local/lib/python3.9/site-packages/airflow/providers/apache/hive/hooks/hive.py", line 886, in get_conn
    return connect(
  File "/home/airflow/.local/lib/python3.9/site-packages/pyhive/hive.py", line 143, in connect
    return Connection(*args, **kwargs)
  File "/home/airflow/.local/lib/python3.9/site-packages/pyhive/hive.py", line 269, in __init__
    self._transport.open()
  File "/home/airflow/.local/lib/python3.9/site-packages/thrift_sasl/__init__.py", line 74, in open
    self._trans.open()
  File "/home/airflow/.local/lib/python3.9/site-packages/thrift/transport/TSocket.py", line 153, in open
    raise TTransportException(type=TTransportException.NOT_OPEN, message=msg)
thrift.transport.TTransport.TTransportException: Could not connect to any of [('192.168.97.11', 10000)]
[2025-04-06T18:59:16.106+0000] {taskinstance.py:441} INFO - ::group::Post task execution logs
[2025-04-06T18:59:16.107+0000] {taskinstance.py:2905} ERROR - Task failed with exception
Traceback (most recent call last):
  File "/home/airflow/.local/lib/python3.9/site-packages/airflow/models/taskinstance.py", line 465, in _execute_task
    result = _execute_callable(context=context, **execute_callable_kwargs)
  File "/home/airflow/.local/lib/python3.9/site-packages/airflow/models/taskinstance.py", line 432, in _execute_callable
    return execute_callable(context=context, **execute_callable_kwargs)
  File "/home/airflow/.local/lib/python3.9/site-packages/airflow/models/baseoperator.py", line 401, in wrapper
    return func(self, *args, **kwargs)
  File "/home/airflow/.local/lib/python3.9/site-packages/airflow/operators/python.py", line 235, in execute
    return_value = self.execute_callable()
  File "/home/airflow/.local/lib/python3.9/site-packages/airflow/operators/python.py", line 252, in execute_callable
    return self.python_callable(*self.op_args, **self.op_kwargs)
  File "/opt/airflow/dags/pipeline.py", line 109, in create_database
    conn = hive_hook.get_conn()
  File "/home/airflow/.local/lib/python3.9/site-packages/airflow/providers/apache/hive/hooks/hive.py", line 886, in get_conn
    return connect(
  File "/home/airflow/.local/lib/python3.9/site-packages/pyhive/hive.py", line 143, in connect
    return Connection(*args, **kwargs)
  File "/home/airflow/.local/lib/python3.9/site-packages/pyhive/hive.py", line 269, in __init__
    self._transport.open()
  File "/home/airflow/.local/lib/python3.9/site-packages/thrift_sasl/__init__.py", line 74, in open
    self._trans.open()
  File "/home/airflow/.local/lib/python3.9/site-packages/thrift/transport/TSocket.py", line 153, in open
    raise TTransportException(type=TTransportException.NOT_OPEN, message=msg)
thrift.transport.TTransport.TTransportException: Could not connect to any of [('192.168.97.11', 10000)]
[2025-04-06T18:59:16.114+0000] {taskinstance.py:1206} INFO - Marking task as FAILED. dag_id=sensor_data_pipeline, task_id=create_database, run_id=manual__2025-04-06T18:54:04.291387+00:00, execution_date=20250406T185404, start_date=20250406T185915, end_date=20250406T185916
[2025-04-06T18:59:16.121+0000] {standard_task_runner.py:110} ERROR - Failed to execute job 88 for task create_database (Could not connect to any of [('192.168.97.11', 10000)]; 163)
[2025-04-06T18:59:16.125+0000] {local_task_job_runner.py:243} INFO - Task exited with return code 1
[2025-04-06T18:59:16.136+0000] {taskinstance.py:3503} INFO - 0 downstream tasks scheduled from follow-on schedule check
[2025-04-06T18:59:16.140+0000] {local_task_job_runner.py:222} INFO - ::endgroup::
